Workbook

Sheet A_Experiment_1
A1: Reactor | B1: Date | C1: Day | D1: DOcathode [mg/L] | E1: ECcathode [mS/cm] | F1: Temp. [C] | G1: pHanode | H1: pHcathode | I1: Pot. [mV] | J1: Ref. Pot. Anode [mV] | K1: Ref. Pot. Cathode [mV] | L1: H2S [mg/L] | M1: SO4^2-anode [mg/L] | N1: Strøm [mA] | O1: Current/volume [mA/L] | P1: Power [muW] | Q1: Power/area [W/m2] | R1: Power/volume [W/L] | S1: H [mol] | T1: S1 [mol/L] | U1: S2 [mol/L] | V1: Tot_S [mol/L] | W1: Tot_S [mg/L]
A2: C1 | B2: 7.3 | C2: 0 | D2: 3.14 | E2: 19.86 | F2: 19.5 | G2: 7.29 | H2: 7.58 | I2: 2.84 | J2: -238.3 | K2: -235.7 | L2: 0.174 | M2: =62.3*10 -> 623 | N2: =I2/1000 -> 0.00284 | O2: =N2/0.4 -> 0.0071 | P2: =N2*I2 -> 0.0080656 | Q2: =(P2*10^-6)/D_Calculation_electrode_area!$H$22 -> 4.480888e-13 | R2: =(P2*10^-6)/0.4 -> 2.0164e-08 | S2: =10^-G2 -> 5.1286138e-08 | T2: =(M2*10^-3/$Z$4) -> 0.0064853543 | U2: =(L2*10^-3/$Z$3) -> 5.105502e-06 | V2: 0.0064904598 | W2: =V2*$Z$5*10^3 -> 208.11659 | Z2: Molarmass | AA2: Unit
A3: C2 | B3: 7.3 | C3: 0 | D3: 4.71 | E3: 20 | F3: 19.4 | G3: 7.34 | H3: 7.45 | I3: 20.9 | J3: -336.4 | K3: -315.7 | L3: 0.274 | M3: =65.8*10 -> 658 | N3: =I3/1000 -> 0.0209 | O3: =N3/0.4 -> 0.05225 | P3: =N3*I3 -> 0.43681 | Q3: =(P3*10^-6)/D_Calculation_electrode_area!$H$22 -> 2.4267217e-11 | R3: =(P3*10^-6)/0.4 -> 1.092025e-06 | S3: =10^-G3 -> 4.5708819e-08 | T3: =(M3*10^-3/$Z$4) -> 0.0068497001 | U3: =(L3*10^-3/$Z$3) -> 8.0396985e-06 | V3: 0.0068577398 | W3: =V3*$Z$5*10^3 -> 219.89343 | Y3: M_H2S | Z3: 34.08088 | AA3: g/mol
A4: C3 | B4: 7.3 | C4: 0 | D4: 5.54 | E4: 19.98 | F4: 19.3 | G4: 7.39 | H4: 7.72 | I4: -4.02 | J4: -230.9 | K4: -226 | L4: 0.284 | M4: =54.8*10 -> 548 | N4: =I4/1000 -> -0.00402 | O4: =N4/0.4 -> -0.01005 | P4: =N4*I4 -> 0.0161604 | Q4: =(P4*10^-6)/D_Calculation_electrode_area!$H$22 -> 8.9779982e-13 | R4: =(P4*10^-6)/0.4 -> 4.0401e-08 | S4: =10^-G4 -> 4.0738028e-08 | T4: =(M4*10^-3/$Z$4) -> 0.0057046134 | U4: =(L4*10^-3/$Z$3) -> 8.3331182e-06 | V4: 0.0057129466 | W4: =V4*$Z$5*10^3 -> 183.18563 | Y4: M_SO4 | Z4: 96.0626 | AA4: g/mol
A5: CC1 | B5: 7.3 | C5: 0 | D5: 4.74 | E5: 20 | F5: 19.7 | G5: 7.29 | H5: 7.79 | I5: -396.2 | J5: -458.1 | K5: -52.32 | L5: 0.344 | M5: =62.9*10 -> 629 | N5: =I5/1000 -> -0.3962 | O5: =N5/0.4 -> -0.9905 | P5: =N5*I5 -> 156.97444 | Q5: =(P5*10^-6)/D_Calculation_electrode_area!$H$22 -> 8.7208005e-09 | R5: =(P5*10^-6)/0.4 -> 0.0003924361 | S5: =10^-G5 -> 5.1286138e-08 | T5: =(M5*10^-3/$Z$4) -> 0.0065478136 | U5: =(L5*10^-3/$Z$3) -> 1.0093636e-05 | V5: 0.0065579072 | W5: =V5*$Z$5*10^3 -> 210.2793 | Y5: M_S | Z5: =32.065 -> 32.065 | AA5: g/mol
A6: CC2 | B6: 7.3 | C6: 0 | D6: 6.11 | E6: 20.1 | F6: 19.7 | G6: 7.26 | H6: 7.86 | I6: =-660 -> -660 | J6: -460.4 | K6: 215.15 | L6: 0.434 | M6: =56.5*10 -> 565 | N6: =I6/1000 -> -0.66 | O6: =N6/0.4 -> -1.65 | P6: =N6*I6 -> 435.6 | Q6: =(P6*10^-6)/D_Calculation_electrode_area!$H$22 -> 2.4199995e-08 | R6: =(P6*10^-6)/0.4 -> 0.001089 | S6: =10^-G6 -> 5.4954087e-08 | T6: =(M6*10^-3/$Z$4) -> 0.0058815814 | U6: =(L6*10^-3/$Z$3) -> 1.2734413e-05 | V6: 0.0058943158 | W6: =V6*$Z$5*10^3 -> 189.00124
A7: CC3 | B7: 7.3 | C7: 0 | D7: 5.71 | E7: 20 | F7: 19.8 | G7: 7.25 | H7: 7.83 | I7: -437.2 | J7: -451 | K7: -11.58 | L7: 0.333 | M7: =63.1*10 -> 631 | N7: =I7/1000 -> -0.4372 | O7: =N7/0.4 -> -1.093 | P7: =N7*I7 -> 191.14384 | Q7: =(P7*10^-6)/D_Calculation_electrode_area!$H$22 -> 1.06191e-08 | R7: =(P7*10^-6)/0.4 -> 0.0004778596 | S7: =10^-G7 -> 5.6234133e-08 | T7: =(M7*10^-3/$Z$4) -> 0.0065686334 | U7: =(L7*10^-3/$Z$3) -> 9.7708745e-06 | V7: 0.0065784042 | W7: =V7*$Z$5*10^3 -> 210.93653
A8: S1 | B8: 7.3 | C8: 0 | D8: 6.62 | E8: 20 | F8: 19.4 | G8: 7.36 | H8: 7.99 | I8: -3.53 | J8: -183.7 | K8: -180.5 | L8: 0.218 | M8: =65*10 -> 650 | N8: =I8/1000 -> -0.00353 | O8: =N8/0.4 -> -0.008825 | P8: =N8*I8 -> 0.0124609 | Q8: =(P8*10^-6)/D_Calculation_electrode_area!$H$21 -> 3.4437049e-06 | R8: =(P8*10^-6)/0.4 -> 3.115225e-08 | S8: =10^-G8 -> 4.3651583e-08 | T8: =(M8*10^-3/$Z$4) -> 0.0067664211 | U8: =(L8*10^-3/$Z$3) -> 6.3965484e-06 | V8: 0.0067728176 | W8: =V8*$Z$5*10^3 -> 217.1704
A9: S2 | B9: 7.3 | C9: 0 | D9: 6.63 | E9: 18.98 | F9: 19.4 | G9: 7.36 | H9: 7.9 | I9: -3.83 | J9: -216.1 | K9: -213.9 | L9: 0.377 | M9: =67.8*10 -> 678 | N9: =I9/1000 -> -0.00383 | O9: =N9/0.4 -> -0.009575 | P9: =N9*I9 -> 0.0146689 | Q9: =(P9*10^-6)/D_Calculation_electrode_area!$H$21 -> 4.0539097e-06 | R9: =(P9*10^-6)/0.4 -> 3.667225e-08 | S9: =10^-G9 -> 4.3651583e-08 | T9: =(M9*10^-3/$Z$4) -> 0.0070578977 | U9: =(L9*10^-3/$Z$3) -> 1.1061921e-05 | V9: 0.0070689596 | W9: =V9*$Z$5*10^3 -> 226.66619
A10: S3 | B10: 7.3 | C10: 0 | D10: 6.49 | E10: 20 | F10: 19.4 | G10: 7.25 | H10: 8.04 | I10: -2.77 | J10: -208.9 | K10: -206 | L10: 1.17 | M10: =61.4*10 -> 614 | N10: =I10/1000 -> -0.00277 | O10: =N10/0.4 -> -0.006925 | P10: =N10*I10 -> 0.0076729 | Q10: =(P10*10^-6)/D_Calculation_electrode_area!$H$21 -> 2.1204892e-06 | R10: =(P10*10^-6)/0.4 -> 1.918225e-08 | S10: =10^-G10 -> 5.6234133e-08 | T10: =(M10*10^-3/$Z$4) -> 0.0063916654 | U10: =(L10*10^-3/$Z$3) -> 3.4330099e-05 | V10: 0.0064259955 | W10: =V10*$Z$5*10^3 -> 206.04955
A11: RC1 | B11: 7.3 | C11: 0 | D11: 5.71 | E11: 20.1 | F11: 19.7 | G11: 7.36 | H11: 7.94 | L11: 0.479 | M11: =56.7*10 -> 567 | S11: =10^-G11 -> 4.3651583e-08 | T11: =(M11*10^-3/$Z$4) -> 0.0059024011 | U11: =(L11*10^-3/$Z$3) -> 1.4054801e-05 | V11: 0.0059164559 | W11: =V11*$Z$5*10^3 -> 189.71116
A12: RC2 | B12: 7.3 | C12: 0 | D12: 5.17 | E12: 19.99 | F12: 19.6 | G12: 7.32 | H12: 7.89 | L12: 0.297 | M12: =62.6*10 -> 626 | S12: =10^-G12 -> 4.7863009e-08 | T12: =(M12*10^-3/$Z$4) -> 0.006516584 | U12: =(L12*10^-3/$Z$3) -> 8.7145637e-06 | V12: 0.0065252985 | W12: =V12*$Z$5*10^3 -> 209.2337
A13: RC3 | B13: 7.3 | C13: 0 | D13: 5.86 | E13: 20.1 | F13: 19.7 | G13: 7.38 | H13: 7.86 | L13: 0.291 | M13: =57.1*10 -> 571 | S13: =10^-G13 -> 4.1686938e-08 | T13: =(M13*10^-3/$Z$4) -> 0.0059440407 | U13: =(L13*10^-3/$Z$3) -> 8.5385119e-06 | V13: 0.0059525792 | W13: =V13*$Z$5*10^3 -> 190.86945
A14: SC1 | B14: 7.3 | C14: 0 | W14: =V14*$Z$5*10^3 -> 0
A15: SC2 | B15: 7.3 | C15: 0 | W15: =V15*$Z$5*10^3 -> 0
A16: SC3 | B16: 7.3 | C16: 0 | W16: =V16*$Z$5*10^3 -> 0
A17: C1 | B17: 9.3 | C17: 2 | D17: 5.74 | E17: 19.91 | F17: 18.4 | G17: 7.48 | H17: 7.64 | I17: -26.34 | J17: -405.1 | K17: -378.1 | N17: =I17/1000 -> -0.02634 | O17: =N17/0.4 -> -0.06585 | P17: =N17*I17 -> 0.6937956 | Q17: =(P17*10^-6)/D_Calculation_electrode_area!$H$22 -> 3.8544192e-11 | R17: =(P17*10^-6)/0.4 -> 1.734489e-06 | S17: =10^-G17 -> 3.3113112e-08 | W17: =V17*$Z$5*10^3 -> 0
A18: C2 | B18: 9.3 | C18: 2 | D18: 6.43 | E18: 20.3 | F18: 18.5 | G18: 7.51 | H18: 7.76 | I18: -26.61 | J18: -380.13 | K18: -353.4 | N18: =I18/1000 -> -0.02661 | O18: =N18/0.4 -> -0.066525 | P18: =N18*I18 -> 0.7080921 | Q18: =(P18*10^-6)/D_Calculation_electrode_area!$H$22 -> 3.9338442e-11 | R18: =(P18*10^-6)/0.4 -> 1.7702302e-06 | S18: =10^-G18 -> 3.0902954e-08 | W18: =V18*$Z$5*10^3 -> 0
A19: C3 | B19: 9.3 | C19: 2 | D19: 6.95 | E19: 20.2 | F19: 18.4 | G19: 7.52 | H19: 7.94 | I19: -23.13 | J19: -402 | K19: -378.8 | N19: =I19/1000 -> -0.02313 | O19: =N19/0.4 -> -0.057825 | P19: =N19*I19 -> 0.5349969 | Q19: =(P19*10^-6)/D_Calculation_electrode_area!$H$22 -> 2.9722044e-11 | R19: =(P19*10^-6)/0.4 -> 1.3374922e-06 | S19: =10^-G19 -> 3.0199517e-08 | W19: =V19*$Z$5*10^3 -> 0
A20: CC1 | B20: 9.3 | C20: 2 | D20: 7.65 | E20: 20.3 | F20: 18.8 | G20: 7.52 | H20: 7.91 | I20: -455.9 | J20: -459.7 | K20: 4.16 | N20: =I20/1000 -> -0.4559 | O20: =N20/0.4 -> -1.13975 | P20: =N20*I20 -> 207.84481 | Q20: =(P20*10^-6)/D_Calculation_electrode_area!$H$22 -> 1.1546932e-08 | R20: =(P20*10^-6)/0.4 -> 0.00051961202 | S20: =10^-G20 -> 3.0199517e-08 | W20: =V20*$Z$5*10^3 -> 0
A21: CC2 | B21: 9.3 | C21: 2 | D21: 7.26 | E21: 20.3 | F21: 18.8 | G21: 7.5 | H21: 7.88 | I21: =-0.713*1000 -> -713 | J21: -448.9 | K21: 263.1 | N21: =I21/1000 -> -0.713 | O21: =N21/0.4 -> -1.7825 | P21: =N21*I21 -> 508.369 | Q21: =(P21*10^-6)/D_Calculation_electrode_area!$H$22 -> 2.8242717e-08 | R21: =(P21*10^-6)/0.4 -> 0.0012709225 | S21: =10^-G21 -> 3.1622777e-08 | W21: =V21*$Z$5*10^3 -> 0
A22: CC3 | B22: 9.3 | C22: 2 | D22: 7.18 | E22: 20.3 | F22: 18.8 | G22: 7.45 | H22: 7.89 | I22: =-0.477*1000 -> -477 | J22: -450.5 | K22: 26.52 | N22: =I22/1000 -> -0.477 | O22: =N22/0.4 -> -1.1925 | P22: =N22*I22 -> 227.529 | Q22: =(P22*10^-6)/D_Calculation_electrode_area!$H$22 -> 1.2640497e-08 | R22: =(P22*10^-6)/0.4 -> 0.0005688225 | S22: =10^-G22 -> 3.5481339e-08 | W22: =V22*$Z$5*10^3 -> 0
A23: S1 | B23: 9.3 | C23: 2 | D23: 6.74 | E23: 20.2 | F23: 18.6 | G23: 7.51 | H23: 7.85 | I23: -14.76 | J23: -303.1 | K23: -288.8 | N23: =I23/1000 -> -0.01476 | O23: =N23/0.4 -> -0.0369 | P23: =N23*I23 -> 0.2178576 | Q23: =(P23*10^-6)/D_Calculation_electrode_area!$H$21 -> 6.0207312e-05 | R23: =(P23*10^-6)/0.4 -> 5.44644e-07 | S23: =10^-G23 -> 3.0902954e-08 | W23: =V23*$Z$5*10^3 -> 0
A24: S2 | B24: 9.3 | C24: 2 | D24: 7.15 | E24: 20.3 | F24: 18.6 | G24: 7.54 | H24: 8.05 | I24: -29.61 | J24: -387.6 | K24: -358.1 | N24: =I24/1000 -> -0.02961 | O24: =N24/0.4 -> -0.074025 | P24: =N24*I24 -> 0.8767521 | Q24: =(P24*10^-6)/D_Calculation_electrode_area!$H$21 -> 0.00024229996 | R24: =(P24*10^-6)/0.4 -> 2.1918802e-06 | S24: =10^-G24 -> 2.8840315e-08 | W24: =V24*$Z$5*10^3 -> 0
A25: S3 | B25: 9.3 | C25: 2 | D25: 7.17 | E25: 20.3 | F25: 18.5 | G25: 7.43 | H25: 8.2 | I25: -26.67 | J25: -385 | K25: -358.4 | N25: =I25/1000 -> -0.02667 | O25: =N25/0.4 -> -0.066675 | P25: =N25*I25 -> 0.7112889 | Q25: =(P25*10^-6)/D_Calculation_electrode_area!$H$21 -> 0.00019657241 | R25: =(P25*10^-6)/0.4 -> 1.7782223e-06 | S25: =10^-G25 -> 3.7153523e-08 | W25: =V25*$Z$5*10^3 -> 0
A26: RC1 | B26: 9.3 | C26: 2 | D26: 8.05 | E26: 20.3 | F26: 18.8 | G26: 7.51 | H26: 8.04 | S26: =10^-G26 -> 3.0902954e-08 | W26: =V26*$Z$5*10^3 -> 0
A27: RC2 | B27: 9.3 | C27: 2 | D27: 7.15 | E27: 20.3 | F27: 18.8 | G27: 7.56 | H27: 7.95 | S27: =10^-G27 -> 2.7542287e-08 | W27: =V27*$Z$5*10^3 -> 0
A28: RC3 | B28: 9.3 | C28: 2 | D28: 7.42 | E28: 20.4 | F28: 18.8 | G28: 7.51 | H28: 8.01 | S28: =10^-G28 -> 3.0902954e-08 | W28: =V28*$Z$5*10^3 -> 0
A29: SC1 | B29: 9.3 | C29: 2 | D29: 8.87 | E29: 19.84 | F29: 19 | G29: 7.71 | H29: 8.34 | I29: -442.9 | J29: -420.3 | K29: 22.88 | N29: =I29/1000 -> -0.4429 | O29: =N29/0.4 -> -1.10725 | P29: =N29*I29 -> 196.16041 | Q29: =(P29*10^-6)/D_Calculation_electrode_area!$H$21 -> 0.054211058 | R29: =(P29*10^-6)/0.4 -> 0.00049040102 | S29: =10^-G29 -> 1.9498446e-08 | W29: =V29*$Z$5*10^3 -> 0
A30: SC2 | B30: 9.3 | C30: 2 | D30: 8.98 | E30: 19.79 | F30: 19.1 | G30: 7.75 | H30: 8.37 | I30: -494 | J30: -337.2 | K30: 55.11 | N30: =I30/1000 -> -0.494 | O30: =N30/0.4 -> -1.235 | P30: =N30*I30 -> 244.036 | Q30: =(P30*10^-6)/D_Calculation_electrode_area!$H$21 -> 0.067441997 | R30: =(P30*10^-6)/0.4 -> 0.00061009 | S30: =10^-G30 -> 1.7782794e-08 | W30: =V30*$Z$5*10^3 -> 0
A31: SC3 | B31: 9.3 | C31: 2 | D31: 9.01 | E31: 19.89 | F31: 19.2 | G31: 7.81 | H31: 8.36 | I31: -477.2 | J31: -331.4 | K31: 39.07 | N31: =I31/1000 -> -0.4772 | O31: =N31/0.4 -> -1.193 | P31: =N31*I31 -> 227.71984 | Q31: =(P31*10^-6)/D_Calculation_electrode_area!$H$21 -> 0.062932849 | R31: =(P31*10^-6)/0.4 -> 0.0005692996 | S31: =10^-G31 -> 1.5488166e-08 | W31: =V31*$Z$5*10^3 -> 0
A32: C1 | B32: 11.3 | C32: 4 | D32: 5.95 | E32: 20.2 | F32: 18.6 | G32: 7.36 | H32: 8.06 | I32: -18.56 | J32: -331.9 | K32: -313.3 | N32: =I32/1000 -> -0.01856 | O32: =N32/0.4 -> -0.0464 | P32: =N32*I32 -> 0.3444736 | Q32: =(P32*10^-6)/D_Calculation_electrode_area!$H$22 -> 1.9137418e-11 | R32: =(P32*10^-6)/0.4 -> 8.61184e-07 | S32: =10^-G32 -> 4.3651583e-08 | W32: =V32*$Z$5*10^3 -> 0
A33: C2 | B33: 11.3 | C33: 4 | D33: 6.72 | E33: 20.5 | F33: 18.5 | G33: 7.48 | H33: 8.28 | I33: -30.99 | J33: -390.3 | K33: -359.6 | N33: =I33/1000 -> -0.03099 | O33: =N33/0.4 -> -0.077475 | P33: =N33*I33 -> 0.9603801 | Q33: =(P33*10^-6)/D_Calculation_electrode_area!$H$22 -> 5.3354439e-11 | R33: =(P33*10^-6)/0.4 -> 2.4009502e-06 | S33: =10^-G33 -> 3.3113112e-08 | W33: =V33*$Z$5*10^3 -> 0
A34: C3 | B34: 11.3 | C34: 4 | D34: 6.95 | E34: 20.4 | F34: 18.5 | G34: 7.51 | H34: 8.21 | I34: -15.12 | J34: -344.7 | K34: -330 | N34: =I34/1000 -> -0.01512 | O34: =N34/0.4 -> -0.0378 | P34: =N34*I34 -> 0.2286144 | Q34: =(P34*10^-6)/D_Calculation_electrode_area!$H$22 -> 1.2700797e-11 | R34: =(P34*10^-6)/0.4 -> 5.71536e-07 | S34: =10^-G34 -> 3.0902954e-08 | W34: =V34*$Z$5*10^3 -> 0
A35: CC1 | B35: 11.3 | C35: 4 | D35: 7.23 | E35: 20.4 | F35: 18.8 | G35: 7.52 | H35: 8.18 | I35: -462.7 | J35: -453.7 | K35: 12.48 | N35: =I35/1000 -> -0.4627 | O35: =N35/0.4 -> -1.15675 | P35: =N35*I35 -> 214.09129 | Q35: =(P35*10^-6)/D_Calculation_electrode_area!$H$22 -> 1.1893958e-08 | R35: =(P35*10^-6)/0.4 -> 0.00053522822 | S35: =10^-G35 -> 3.0199517e-08 | W35: =V35*$Z$5*10^3 -> 0
A36: CC2 | B36: 11.3 | C36: 4 | D36: 7.23 | E36: 20.4 | F36: 18.9 | G36: 7.57 | H36: 8.16 | I36: -689 | J36: -435.8 | K36: 257.5 | N36: =I36/1000 -> -0.689 | O36: =N36/0.4 -> -1.7225 | P36: =N36*I36 -> 474.721 | Q36: =(P36*10^-6)/D_Calculation_electrode_area!$H$22 -> 2.6373384e-08 | R36: =(P36*10^-6)/0.4 -> 0.0011868025 | S36: =10^-G36 -> 2.6915348e-08 | W36: =V36*$Z$5*10^3 -> 0
A37: CC3 | B37: 11.3 | C37: 4 | D37: 7.08 | E37: 20.4 | F37: 18.8 | G37: 7.46 | H37: 8.12 | I37: -539.6 | J37: -449.1 | K37: 91.7 | N37: =I37/1000 -> -0.5396 | O37: =N37/0.4 -> -1.349 | P37: =N37*I37 -> 291.16816 | Q37: =(P37*10^-6)/D_Calculation_electrode_area!$H$22 -> 1.6176006e-08 | R37: =(P37*10^-6)/0.4 -> 0.0007279204 | S37: =10^-G37 -> 3.4673685e-08 | W37: =V37*$Z$5*10^3 -> 0
A38: S1 | B38: 11.3 | C38: 4 | D38: 6.67 | E38: 20.3 | F38: 18.7 | G38: 7.47 | H38: 8.17 | I38: -22.42 | J38: -341.5 | K38: -318.7 | N38: =I38/1000 -> -0.02242 | O38: =N38/0.4 -> -0.05605 | P38: =N38*I38 -> 0.5026564 | Q38: =(P38*10^-6)/D_Calculation_electrode_area!$H$21 -> 0.00013891455 | R38: =(P38*10^-6)/0.4 -> 1.256641e-06 | S38: =10^-G38 -> 3.3884416e-08 | W38: =V38*$Z$5*10^3 -> 0
A39: S2 | B39: 11.3 | C39: 4 | D39: 7.53 | E39: 20.4 | F39: 18.7 | G39: 7.43 | H39: 8.34 | I39: -32.34 | J39: -386.4 | K39: -354 | N39: =I39/1000 -> -0.03234 | O39: =N39/0.4 -> -0.08085 | P39: =N39*I39 -> 1.0458756 | Q39: =(P39*10^-6)/D_Calculation_electrode_area!$H$21 -> 0.00028903907 | R39: =(P39*10^-6)/0.4 -> 2.614689e-06 | S39: =10^-G39 -> 3.7153523e-08 | W39: =V39*$Z$5*10^3 -> 0
A40: S3 | B40: 11.3 | C40: 4 | D40: 7.63 | E40: 20.4 | F40: 18.7 | G40: 7.4 | H40: 8.38 | I40: -19.59 | J40: -349.8 | K40: -330 | N40: =I40/1000 -> -0.01959 | O40: =N40/0.4 -> -0.048975 | P40: =N40*I40 -> 0.3837681 | Q40: =(P40*10^-6)/D_Calculation_electrode_area!$H$21 -> 0.00010605848 | R40: =(P40*10^-6)/0.4 -> 9.5942025e-07 | S40: =10^-G40 -> 3.9810717e-08 | W40: =V40*$Z$5*10^3 -> 0
...

Sheet B_Experiment_2
A1: Box | B1: Date | C1: Day | D1: Pot. [mV] | E1: Ref. Pot. Anode [mV] | F1: Ref. Pot. Cathode [mV] | G1: DO [mg/L] | H1: EC [mS/cm] | I1: pH | J1: H2S [mg/L] | K1: SO4^2- [mg/L] | L1: Temp. [C] | M1: Strøm [mA] | N1: Power [muW] | O1: Power/area [W/m2] | P1: H [mol/L] | Q1: DO [mol/L] | R1: S1 [mol/L] | S1: S2 [mol/L] | T1: Tot_S [mol/L] | W1: Molarmass | X1: Unit
A2: LL1 | B2: 7.3 | C2: 0 | D2: -25.71 | E2: 217 | F2: 191.3 | G2: 4.27 | H2: 18.63 | I2: 7.46 | J2: 0 | K2: =68.8*10 -> 688 | L2: 19.6 | M2: =D2/1000 -> -0.02571 | N2: =M2*D2 -> 0.6610041 | O2: =(N2*10^-6)/D_Calculation_electrode_area!$B$19 -> 5.1973178e-05 | P2: =10^-I2*4 -> 1.3869474e-07 | Q2: =(G2*10^-6)/31.9988 -> 1.334425e-07 | R2: =(K2*10^-3/$W$3)*0.33 -> 0.0023634588 | S2: =(J2*10^-3/$W$2)*0.941 -> 0 | T2: =R2+S2 -> 0.0023634588 | V2: M_H2S | W2: 34.08088 | X2: g/mol
A3: LL2 | B3: 7.3 | C3: 0 | D3: -15.28 | E3: 191.7 | F3: 175.9 | G3: 3.91 | H3: 18.45 | I3: 7.55 | J3: 0 | K3: =64.7*10 -> 647 | L3: 19.5 | M3: =D3/1000 -> -0.01528 | N3: =M3*D3 -> 0.2334784 | O3: =(N3*10^-6)/D_Calculation_electrode_area!$B$19 -> 1.835785e-05 | P3: =10^-I3*4 -> 1.1273532e-07 | Q3: =(G3*10^-6)/31.9988 -> 1.2219208e-07 | R3: =(K3*10^-3/$W$3)*0.33 -> 0.0022226132 | S3: =(J3*10^-3/$W$2)*0.941 -> 0 | T3: =R3+S3 -> 0.0022226132 | V3: M_SO4 | W3: 96.0626 | X3: g/mol
A4: LL3 | B4: 7.3 | C4: 0 | D4: -30.79 | E4: 220.6 | F4: 190.1 | G4: 5.01 | H4: 18.4 | I4: 7.56 | J4: 0 | K4: =77.6*10 -> 776 | L4: 19.6 | M4: =D4/1000 -> -0.03079 | N4: =M4*D4 -> 0.9480241 | O4: =(N4*10^-6)/D_Calculation_electrode_area!$B$19 -> 7.4540877e-05 | P4: =10^-I4*4 -> 1.1016915e-07 | Q4: =(G4*10^-6)/31.9988 -> 1.5656837e-07 | R4: =(K4*10^-3/$W$3)*0.33 -> 0.0026657617 | S4: =(J4*10^-3/$W$2)*0.941 -> 0 | T4: =R4+S4 -> 0.0026657617
A5: SL1 | B5: 7.3 | C5: 0 | D5: 57.25 | E5: 335.8 | F5: 279.2 | G5: 4.55 | H5: 18.71 | I5: 7.66 | J5: 0 | K5: =66.5*10 -> 665 | L5: 19.7 | M5: =D5/1000 -> 0.05725 | N5: =M5*D5 -> 3.2775625 | O5: =(N5*10^-6)/D_Calculation_electrode_area!$B$19 -> 0.00025770693 | P5: =10^-I5*4 -> 8.7510465e-08 | Q5: =(G5*10^-6)/31.9988 -> 1.4219283e-07 | R5: =(K5*10^-3/$W$3)*0.33 -> 0.0022844478 | S5: =(J5*10^-3/$W$2)*0.941 -> 0 | T5: =R5+S5 -> 0.0022844478
A6: SL2 | B6: 7.3 | C6: 0 | D6: -34.72 | E6: 303.6 | F6: 269.5 | G6: 5.11 | H6: 18.24 | I6: 7.68 | J6: 0 | K6: =63.3*10 -> 633 | L6: 19.7 | M6: =D6/1000 -> -0.03472 | N6: =M6*D6 -> 1.2054784 | O6: =(N6*10^-6)/D_Calculation_electrode_area!$B$19 -> 9.4783895e-05 | P6: =10^-I6*4 -> 8.3571845e-08 | Q6: =(G6*10^-6)/31.9988 -> 1.5969349e-07 | R6: =(K6*10^-3/$W$3)*0.33 -> 0.0021745195 | S6: =(J6*10^-3/$W$2)*0.941 -> 0 | T6: =R6+S6 -> 0.0021745195
A7: SL3 | B7: 7.3 | C7: 0 | D7: -49.7 | E7: 325.8 | F7: 277.6 | G7: 4.37 | H7: 18.82 | I7: 7.71 | J7: 0 | K7: =65.4*10 -> 654 | L7: 19.9 | M7: =D7/1000 -> -0.0497 | N7: =M7*D7 -> 2.47009 | O7: =(N7*10^-6)/D_Calculation_electrode_area!$B$19 -> 0.00019421729 | P7: =10^-I7*4 -> 7.7993784e-08 | Q7: =(G7*10^-6)/31.9988 -> 1.3656762e-07 | R7: =(K7*10^-3/$W$3)*0.33 -> 0.00224666 | S7: =(J7*10^-3/$W$2)*0.941 -> 0 | T7: =R7+S7 -> 0.00224666
A8: C-SL1 | B8: 7.3 | C8: 0 | D8: =-0.764*1000 -> -764 | E8: 468.8 | F8: -289.8 | G8: 5.45 | H8: 18.92 | I8: 7.72 | J8: 0 | K8: =61.7*10 -> 617 | L8: 19.6 | M8: =D8/1000 -> -0.764 | N8: =M8*D8 -> 583.696 | O8: =(N8*10^-6)/D_Calculation_electrode_area!$B$19 -> 0.045894626 | P8: =10^-I8*4 -> 7.6218429e-08 | Q8: =(G8*10^-6)/31.9988 -> 1.7031889e-07 | R8: =(K8*10^-3/$W$3)*0.33 -> 0.0021195554 | S8: =(J8*10^-3/$W$2)*0.941 -> 0 | T8: =R8+S8 -> 0.0021195554
A9: C-SL2 | B9: 7.3 | C9: 0 | D9: =-0.704*1000 -> -704 | E9: 473.6 | F9: -250.7 | G9: 4.84 | H9: 18.98 | I9: 7.73 | J9: 0 | K9: =73.2*10 -> 732 | L9: 19.9 | M9: =D9/1000 -> -0.704 | N9: =M9*D9 -> 495.616 | O9: =(N9*10^-6)/D_Calculation_electrode_area!$B$19 -> 0.038969105 | P9: =10^-I9*4 -> 7.4483485e-08 | Q9: =(G9*10^-6)/31.9988 -> 1.5125567e-07 | R9: =(K9*10^-3/$W$3)*0.33 -> 0.0025146103 | S9: =(J9*10^-3/$W$2)*0.941 -> 0 | T9: =R9+S9 -> 0.0025146103
A10: C-SL3 | B10: 7.3 | C10: 0 | D10: =0.733*-1000 -> -733 | E10: 444.6 | F10: -261.8 | G10: 4.32 | H10: 19.13 | I10: 7.74 | J10: 0 | K10: =76.1*10 -> 761 | L10: 19.8 | M10: =D10/1000 -> -0.733 | N10: =M10*D10 -> 537.289 | O10: =(N10*10^-6)/D_Calculation_electrode_area!$B$19 -> 0.042245754 | P10: =10^-I10*4 -> 7.2788034e-08 | Q10: =(G10*10^-6)/31.9988 -> 1.3500506e-07 | R10: =(K10*10^-3/$W$3)*0.33 -> 0.0026142328 | S10: =(J10*10^-3/$W$2)*0.941 -> 0 | T10: =R10+S10 -> 0.0026142328
A11: CB1 | B11: 7.3 | C11: 0 | G11: 4 | H11: 18.7 | I11: 7.73 | J11: 0 | K11: =66.1*10 -> 661 | L11: 20.1 | P11: =10^-I11*4 -> 7.4483485e-08 | Q11: =(G11*10^-6)/31.9988 -> 1.2500469e-07 | R11: =(K11*10^-3/$W$3)*0.33 -> 0.0022707068 | S11: =(J11*10^-3/$W$2)*0.941 -> 0 | T11: =R11+S11 -> 0.0022707068
A12: CB2 | B12: 7.3 | C12: 0 | G12: 4.42 | H12: 18.9 | I12: 7.75 | J12: 0 | K12: =61.8*10 -> 618 | L12: 20 | P12: =10^-I12*4 -> 7.1131176e-08 | Q12: =(G12*10^-6)/31.9988 -> 1.3813018e-07 | R12: =(K12*10^-3/$W$3)*0.33 -> 0.0021229906 | S12: =(J12*10^-3/$W$2)*0.941 -> 0 | T12: =R12+S12 -> 0.0021229906
A13: CB3 | B13: 7.3 | C13: 0 | G13: 4.07 | H13: 19.28 | I13: 7.76 | J13: 0 | K13: =72.6*10 -> 726 | L13: 19.6 | P13: =10^-I13*4 -> 6.9512033e-08 | Q13: =(G13*10^-6)/31.9988 -> 1.2719227e-07 | R13: =(K13*10^-3/$W$3)*0.33 -> 0.0024939987 | S13: =(J13*10^-3/$W$2)*0.941 -> 0 | T13: =R13+S13 -> 0.0024939987
A14: LL1 | B14: 9.3 | C14: 2 | D14: -136.9 | E14: -415 | F14: -277.7 | G14: 4.78 | H14: 18.79 | I14: 7.78 | L14: 18.8 | M14: =D14/1000 -> -0.1369 | N14: =M14*D14 -> 18.74161 | O14: =(N14*10^-6)/D_Calculation_electrode_area!$B$19 -> 0.0014736081 | P14: =10^-I14*4 -> 6.6383476e-08 | Q14: =(G14*10^-6)/31.9988 -> 1.493806e-07 | R14: =(K14*10^-3/$W$3)*0.33 -> 0 | S14: =(J14*10^-3/$W$2)*0.941 -> 0 | T14: =R14+S14 -> 0
A15: LL2 | B15: 9.3 | C15: 2 | D15: -106.7 | E15: -21.99 | F15: 84.7 | G15: 5.84 | H15: 18.27 | I15: 7.85 | L15: 18.8 | M15: =D15/1000 -> -0.1067 | N15: =M15*D15 -> 11.38489 | O15: =(N15*10^-6)/D_Calculation_electrode_area!$B$19 -> 0.00089516678 | P15: =10^-I15*4 -> 5.6501502e-08 | Q15: =(G15*10^-6)/31.9988 -> 1.8250684e-07 | R15: =(K15*10^-3/$W$3)*0.33 -> 0 | S15: =(J15*10^-3/$W$2)*0.941 -> 0 | T15: =R15+S15 -> 0
A16: LL3 | B16: 9.3 | C16: 2 | D16: -135.6 | E16: -51.08 | F16: 85.2 | G16: 6.4 | H16: 18.38 | I16: 7.72 | L16: 18.8 | M16: =D16/1000 -> -0.1356 | N16: =M16*D16 -> 18.38736 | O16: =(N16*10^-6)/D_Calculation_electrode_area!$B$19 -> 0.0014457543 | P16: =10^-I16*4 -> 7.6218429e-08 | Q16: =(G16*10^-6)/31.9988 -> 2.000075e-07 | R16: =(K16*10^-3/$W$3)*0.33 -> 0 | S16: =(J16*10^-3/$W$2)*0.941 -> 0 | T16: =R16+S16 -> 0
A17: SL1 | B17: 9.3 | C17: 2 | D17: -87.8 | E17: -408.9 | F17: -321.3 | G17: 6.8 | H17: 18.55 | I17: 7.84 | L17: 18.9 | M17: =D17/1000 -> -0.0878 | N17: =M17*D17 -> 7.70884 | O17: =(N17*10^-6)/D_Calculation_electrode_area!$B$19 -> 0.00060612773 | P17: =10^-I17*4 -> 5.7817591e-08 | Q17: =(G17*10^-6)/31.9988 -> 2.1250797e-07 | R17: =(K17*10^-3/$W$3)*0.33 -> 0 | S17: =(J17*10^-3/$W$2)*0.941 -> 0 | T17: =R17+S17 -> 0
A18: SL2 | B18: 9.3 | C18: 2 | D18: -142.7 | E18: -128.6 | F18: 11.54 | G18: 6.27 | H18: 18.14 | I18: 7.87 | L18: 19 | M18: =D18/1000 -> -0.1427 | N18: =M18*D18 -> 20.36329 | O18: =(N18*10^-6)/D_Calculation_electrode_area!$B$19 -> 0.001601117 | P18: =10^-I18*4 -> 5.3958515e-08 | Q18: =(G18*10^-6)/31.9988 -> 1.9594485e-07 | R18: =(K18*10^-3/$W$3)*0.33 -> 0 | S18: =(J18*10^-3/$W$2)*0.941 -> 0 | T18: =R18+S18 -> 0
A19: SL3 | B19: 9.3 | C19: 2 | D19: -196.1 | E19: -416.7 | F19: -218.9 | G19: 6.15 | H19: 18.75 | I19: 7.97 | L19: 19 | M19: =D19/1000 -> -0.1961 | N19: =M19*D19 -> 38.45521 | O19: =(N19*10^-6)/D_Calculation_electrode_area!$B$19 -> 0.0030236416 | P19: =10^-I19*4 -> 4.2860772e-08 | Q19: =(G19*10^-6)/31.9988 -> 1.9219471e-07 | R19: =(K19*10^-3/$W$3)*0.33 -> 0 | S19: =(J19*10^-3/$W$2)*0.941 -> 0 | T19: =R19+S19 -> 0
A20: C-SL1 | B20: 9.3 | C20: 2 | D20: =-0.761*1000 -> -761 | E20: -450.1 | F20: 312 | G20: 6.5 | H20: 18.9 | I20: 7.9 | L20: 18.9 | M20: =D20/1000 -> -0.761 | N20: =M20*D20 -> 579.121 | O20: =(N20*10^-6)/D_Calculation_electrode_area!$B$19 -> 0.045534905 | P20: =10^-I20*4 -> 5.0357016e-08 | Q20: =(G20*10^-6)/31.9988 -> 2.0313262e-07 | R20: =(K20*10^-3/$W$3)*0.33 -> 0 | S20: =(J20*10^-3/$W$2)*0.941 -> 0 | T20: =R20+S20 -> 0
A21: C-SL2 | B21: 9.3 | C21: 2 | D21: =-0.778*1000 -> -778 | E21: -450.2 | F21: 318.4 | G21: 6.44 | H21: 18.96 | I21: 7.83 | L21: 18.9 | M21: =D21/1000 -> -0.778 | N21: =M21*D21 -> 605.284 | O21: =(N21*10^-6)/D_Calculation_electrode_area!$B$19 -> 0.047592039 | P21: =10^-I21*4 -> 5.9164336e-08 | Q21: =(G21*10^-6)/31.9988 -> 2.0125755e-07 | R21: =(K21*10^-3/$W$3)*0.33 -> 0 | S21: =(J21*10^-3/$W$2)*0.941 -> 0 | T21: =R21+S21 -> 0
A22: C-SL3 | B22: 9.3 | C22: 2 | D22: =-0.778*1000 -> -778 | E22: -454.3 | F22: 342.7 | G22: 5.25 | H22: 18.98 | I22: 7.89 | L22: 19.1 | M22: =D22/1000 -> -0.778 | N22: =M22*D22 -> 605.284 | O22: =(N22*10^-6)/D_Calculation_electrode_area!$B$19 -> 0.047592039 | P22: =10^-I22*4 -> 5.1529982e-08 | Q22: =(G22*10^-6)/31.9988 -> 1.6406865e-07 | R22: =(K22*10^-3/$W$3)*0.33 -> 0 | S22: =(J22*10^-3/$W$2)*0.941 -> 0 | T22: =R22+S22 -> 0
A23: CB1 | B23: 9.3 | C23: 2 | G23: 6.15 | H23: 18.82 | I23: 7.92 | L23: 19 | P23: =10^-I23*4 -> 4.8090577e-08 | Q23: =(G23*10^-6)/31.9988 -> 1.9219471e-07 | R23: =(K23*10^-3/$W$3)*0.33 -> 0 | S23: =(J23*10^-3/$W$2)*0.941 -> 0 | T23: =R23+S23 -> 0
A24: CB2 | B24: 9.3 | C24: 2 | G24: 5.58 | H24: 18.73 | I24: 7.83 | L24: 19.1 | P24: =10^-I24*4 -> 5.9164336e-08 | Q24: =(G24*10^-6)/31.9988 -> 1.7438154e-07 | R24: =(K24*10^-3/$W$3)*0.33 -> 0 | S24: =(J24*10^-3/$W$2)*0.941 -> 0 | T24: =R24+S24 -> 0
A25: CB3 | B25: 9.3 | C25: 2 | G25: 5.83 | H25: 19.13 | I25: 7.76 | L25: 19 | P25: =10^-I25*4 -> 6.9512033e-08 | Q25: =(G25*10^-6)/31.9988 -> 1.8219433e-07 | R25: =(K25*10^-3/$W$3)*0.33 -> 0 | S25: =(J25*10^-3/$W$2)*0.941 -> 0 | T25: =R25+S25 -> 0
A26: LL1 | B26: 11.3 | C26: 4 | D26: -414.6 | E26: -310.9 | F26: 103.9 | G26: 5.24 | H26: 18.9 | I26: 8.32 | L26: 18.8 | M26: =D26/1000 -> -0.4146 | N26: =M26*D26 -> 171.89316 | O26: =(N26*10^-6)/D_Calculation_electrode_area!$B$19 -> 0.01351555 | P26: =10^-I26*4 -> 1.9145204e-08 | Q26: =(G26*10^-6)/31.9988 -> 1.6375614e-07 | R26: =(K26*10^-3/$W$3)*0.33 -> 0 | S26: =(J26*10^-3/$W$2)*0.941 -> 0 | T26: =R26+S26 -> 0
A27: LL2 | B27: 11.3 | C27: 4 | D27: -181.3 | E27: -78.5 | F27: 105.3 | G27: 6.79 | H27: 18.31 | I27: 8.24 | L27: 18.8 | M27: =D27/1000 -> -0.1813 | N27: =M27*D27 -> 32.86969 | O27: =(N27*10^-6)/D_Calculation_electrode_area!$B$19 -> 0.0025844654 | P27: =10^-I27*4 -> 2.3017597e-08 | Q27: =(G27*10^-6)/31.9988 -> 2.1219546e-07 | R27: =(K27*10^-3/$W$3)*0.33 -> 0 | S27: =(J27*10^-3/$W$2)*0.941 -> 0 | T27: =R27+S27 -> 0
A28: LL3 | B28: 11.3 | C28: 4 | D28: -255 | E28: -147.5 | F28: 108.7 | G28: 5.83 | H28: 18.44 | I28: 8.11 | L28: 18.8 | M28: =D28/1000 -> -0.255 | N28: =M28*D28 -> 65.025 | O28: =(N28*10^-6)/D_Calculation_electrode_area!$B$19 -> 0.0051127608 | P28: =10^-I28*4 -> 3.1049885e-08 | Q28: =(G28*10^-6)/31.9988 -> 1.8219433e-07 | R28: =(K28*10^-3/$W$3)*0.33 -> 0 | S28: =(J28*10^-3/$W$2)*0.941 -> 0 | T28: =R28+S28 -> 0
A29: SL1 | B29: 11.3 | C29: 4 | D29: -254.3 | E29: -232.5 | F29: 20 | G29: 6.1 | H29: 18.64 | I29: 8.17 | L29: 18.8 | M29: =D29/1000 -> -0.2543 | N29: =M29*D29 -> 64.66849 | O29: =(N29*10^-6)/D_Calculation_electrode_area!$B$19 -> 0.0050847293 | P29: =10^-I29*4 -> 2.7043319e-08 | Q29: =(G29*10^-6)/31.9988 -> 1.9063215e-07 | R29: =(K29*10^-3/$W$3)*0.33 -> 0 | S29: =(J29*10^-3/$W$2)*0.941 -> 0 | T29: =R29+S29 -> 0
A30: SL2 | B30: 11.3 | C30: 4 | D30: -200.2 | E30: -125.3 | F30: 74.8 | G30: 6.18 | H30: 18.23 | I30: 8.18 | L30: 18.7 | M30: =D30/1000 -> -0.2002 | N30: =M30*D30 -> 40.08004 | O30: =(N30*10^-6)/D_Calculation_electrode_area!$B$19 -> 0.0031513981 | P30: =10^-I30*4 -> 2.6427738e-08 | Q30: =(G30*10^-6)/31.9988 -> 1.9313224e-07 | R30: =(K30*10^-3/$W$3)*0.33 -> 0 | S30: =(J30*10^-3/$W$2)*0.941 -> 0 | T30: =R30+S30 -> 0
A31: SL3 | B31: 11.3 | C31: 4 | D31: -264.5 | E31: -409.4 | F31: -148.7 | G31: 5.97 | H31: 18.81 | I31: 8.39 | L31: 18.9 | M31: =D31/1000 -> -0.2645 | N31: =M31*D31 -> 69.96025 | O31: =(N31*10^-6)/D_Calculation_electrode_area!$B$19 -> 0.0055008078 | P31: =10^-I31*4 -> 1.6295211e-08 | Q31: =(G31*10^-6)/31.9988 -> 1.865695e-07 | R31: =(K31*10^-3/$W$3)*0.33 -> 0 | S31: =(J31*10^-3/$W$2)*0.941 -> 0 | T31: =R31+S31 -> 0
A32: C-SL1 | B32: 11.3 | C32: 4 | D32: -776 | E32: -454.3 | F32: 317.6 | G32: 6.85 | H32: 18.99 | I32: 8.15 | L32: 18.9 | M32: =D32/1000 -> -0.776 | N32: =M32*D32 -> 602.176 | O32: =(N32*10^-6)/D_Calculation_electrode_area!$B$19 -> 0.047347664 | P32: =10^-I32*4 -> 2.8317831e-08 | Q32: =(G32*10^-6)/31.9988 -> 2.1407053e-07 | R32: =(K32*10^-3/$W$3)*0.33 -> 0 | S32: =(J32*10^-3/$W$2)*0.941 -> 0 | T32: =R32+S32 -> 0
A33: C-SL2 | B33: 11.3 | C33: 4 | D33: -797 | E33: -469.9 | F33: 328.9 | G33: 5.6 | H33: 19.03 | I33: 8.08 | L33: 19 | M33: =D33/1000 -> -0.797 | N33: =M33*D33 -> 635.209 | O33: =(N33*10^-6)/D_Calculation_electrode_area!$B$19 -> 0.04994497 | P33: =10^-I33*4 -> 3.3270551e-08 | Q33: =(G33*10^-6)/31.9988 -> 1.7500656e-07 | R33: =(K33*10^-3/$W$3)*0.33 -> 0 | S33: =(J33*10^-3/$W$2)*0.941 -> 0 | T33: =R33+S33 -> 0
A34: C-SL3 | B34: 11.3 | C34: 4 | D34: -762 | E34: -457.2 | F34: 305.9 | G34: 6.14 | H34: 19.14 | I34: 8.12 | L34: 19 | M34: =D34/1000 -> -0.762 | N34: =M34*D34 -> 580.644 | O34: =(N34*10^-6)/D_Calculation_electrode_area!$B$19 -> 0.045654655 | P34: =10^-I34*4 -> 3.0343103e-08 | Q34: =(G34*10^-6)/31.9988 -> 1.918822e-07 | R34: =(K34*10^-3/$W$3)*0.33 -> 0 | S34: =(J34*10^-3/$W$2)*0.941 -> 0 | T34: =R34+S34 -> 0
A35: CB1 | B35: 11.3 | C35: 4 | G35: 6.19 | H35: 19 | I35: 8.2 | L35: 19 | P35: =10^-I35*4 -> 2.5238294e-08 | Q35: =(G35*10^-6)/31.9988 -> 1.9344475e-07 | R35: =(K35*10^-3/$W$3)*0.33 -> 0 | S35: =(J35*10^-3/$W$2)*0.941 -> 0 | T35: =R35+S35 -> 0
A36: CB2 | B36: 11.3 | C36: 4 | G36: 6.09 | H36: 18.84 | I36: 8.15 | L36: 19.1 | P36: =10^-I36*4 -> 2.8317831e-08 | Q36: =(G36*10^-6)/31.9988 -> 1.9031964e-07 | R36: =(K36*10^-3/$W$3)*0.33 -> 0 | S36: =(J36*10^-3/$W$2)*0.941 -> 0 | T36: =R36+S36 -> 0
A37: CB3 | B37: 11.3 | C37: 4 | G37: 6.24 | H37: 19.2 | I37: 8.08 | L37: 19.1 | P37: =10^-I37*4 -> 3.3270551e-08 | Q37: =(G37*10^-6)/31.9988 -> 1.9500731e-07 | R37: =(K37*10^-3/$W$3)*0.33 -> 0 | S37: =(J37*10^-3/$W$2)*0.941 -> 0 | T37: =R37+S37 -> 0
A38: LL1 | B38: 14.3 | C38: 7 | D38: -441.4 | E38: -338.1 | F38: 101.2 | G38: 5.54 | H38: 18.74 | I38: 8.386 | L38: 19 | M38: =D38/1000 -> -0.4414 | N38: =M38*D38 -> 194.83396 | O38: =(N38*10^-6)/D_Calculation_electrode_area!$B$19 -> 0.01531933 | P38: =10^-I38*4 -> 1.6445989e-08 | Q38: =(G38*10^-6)/31.9988 -> 1.7313149e-07 | R38: =(K38*10^-3/$W$3)*0.33 -> 0 | S38: =(J38*10^-3/$W$2)*0.941 -> 0 | T38: =R38+S38 -> 0
A39: LL2 | B39: 14.3 | C39: 7 | D39: -270.6 | E39: -171.8 | F39: 100 | G39: 5.34 | H39: 18.27 | I39: 8.237 | L39: 18.9 | M39: =D39/1000 -> -0.2706 | N39: =M39*D39 -> 73.22436 | O39: =(N39*10^-6)/D_Calculation_electrode_area!$B$19 -> 0.005757457 | P39: =10^-I39*4 -> 2.3177148e-08 | Q39: =(G39*10^-6)/31.9988 -> 1.6688126e-07 | R39: =(K39*10^-3/$W$3)*0.33 -> 0 | S39: =(J39*10^-3/$W$2)*0.941 -> 0 | T39: =R39+S39 -> 0
A40: LL3 | B40: 14.3 | C40: 7 | D40: -421.7 | E40: -229.4 | F40: 197.1 | G40: 5.55 | H40: 18.36 | I40: 8.239 | L40: 18.7 | M40: =D40/1000 -> -0.4217 | N40: =M40*D40 -> 177.83089 | O40: =(N40*10^-6)/D_Calculation_electrode_area!$B$19 -> 0.013982419 | P40: =10^-I40*4 -> 2.3070659e-08 | Q40: =(G40*10^-6)/31.9988 -> 1.73444e-07 | R40: =(K40*10^-3/$W$3)*0.33 -> 0 | S40: =(J40*10^-3/$W$2)*0.941 -> 0 | T40: =R40+S40 -> 0
...

Sheet C_Data_PowerPolarization_curve
A1: Treatment | B1: Resistor | C1: Pot [mV] | D1: Pot [V] | E1: Power/area [W/m2] | F1: Current/area [A/m2]
A2: C1 | B2: 10000 | C2: -514.8 | D2: =C2*10^-3 -> -0.5148 | E2: =((D2)^2/B2)/D_Calculation_electrode_area!$H$22 -> 1.4723277e-09 | F2: =E2/D2 -> -2.8599994e-09
A3: C1 | B3: 6800 | C3: -474.4 | D3: =C3*10^-3 -> -0.4744 | E3: =((D3)^2/B3)/D_Calculation_electrode_area!$H$22 -> 1.8386872e-09 | F3: =E3/D3 -> -3.8758162e-09
A4: C1 | B4: 4700 | C4: -415.2 | D4: =C4*10^-3 -> -0.4152 | E4: =((D4)^2/B4)/D_Calculation_electrode_area!$H$22 -> 2.0377187e-09 | F4: =E4/D4 -> -4.9078004e-09
A5: C1 | B5: 1000 | C5: -162.3 | D5: =C5*10^-3 -> -0.1623 | E5: =((D5)^2/B5)/D_Calculation_electrode_area!$H$22 -> 1.4634047e-09 | F5: =E5/D5 -> -9.0166649e-09
A6: C1 | B6: 560 | C6: -103.9 | D6: =C6*10^-3 -> -0.1039 | E6: =((D6)^2/B6)/D_Calculation_electrode_area!$H$22 -> 1.0709532e-09 | F6: =E6/D6 -> -1.0307538e-08
A7: C1 | B7: 100 | C7: -21.09 | D7: =C7*10^-3 -> -0.02109 | E7: =((D7)^2/B7)/D_Calculation_electrode_area!$H$22 -> 2.4710445e-10 | F7: =E7/D7 -> -1.1716664e-08
A8: C1 | B8: 10 | C8: -2.16 | D8: =C8*10^-3 -> -0.00216 | E8: =((D8)^2/B8)/D_Calculation_electrode_area!$H$22 -> 2.5919995e-11 | F8: =E8/D8 -> -1.1999998e-08
A9: C2 | B9: 10000 | C9: -499.2 | D9: =C9*10^-3 -> -0.4992 | E9: =((D9)^2/B9)/D_Calculation_electrode_area!$H$22 -> 1.3844477e-09 | F9: =E9/D9 -> -2.7733328e-09
A10: C2 | B10: 6800 | C10: -453.6 | D10: =C10*10^-3 -> -0.4536 | E10: =((D10)^2/B10)/D_Calculation_electrode_area!$H$22 -> 1.6809879e-09 | F10: =E10/D10 -> -3.7058816e-09
A11: C2 | B11: 4700 | C11: -387.8 | D11: =C11*10^-3 -> -0.3878 | E11: =((D11)^2/B11)/D_Calculation_electrode_area!$H$22 -> 1.7776455e-09 | F11: =E11/D11 -> -4.5839234e-09
A12: C2 | B12: 1000 | C12: -125.5 | D12: =C12*10^-3 -> -0.1255 | E12: =((D12)^2/B12)/D_Calculation_electrode_area!$H$22 -> 8.7501371e-10 | F12: =E12/D12 -> -6.9722208e-09
A13: C2 | B13: 560 | C13: -76.2 | D13: =C13*10^-3 -> -0.0762 | E13: =((D13)^2/B13)/D_Calculation_electrode_area!$H$22 -> 5.760356e-10 | F13: =E13/D13 -> -7.5595223e-09
... A22: C3 | B22: 10 | C22: -3.17 | D22: =C22*10^-3 -> -0.00317 | E22: =((D22)^2/B22)/D_Calculation_electrode_area!$H$22 -> 5.5827211e-11 | F22: =E22/D22 -> -1.7611108e-08
A23: S1 | B23: 10000 | C23: -440 | D23: =C23*10^-3 -> -0.44 | E23: =((D23)^2/B23)/D_Calculation_electrode_area!$H$21 -> 0.0053503461 | F23: =E23/D23 -> -0.012159878
A24: S1 | B24: 6800 | C24: -390 | D24: =C24*10^-3 -> -0.39 | E24: =((D24)^2/B24)/D_Calculation_electrode_area!$H$21 -> 0.006181542 | F24: =E24/D24 -> -0.015850108
A25: S1 | B25: 4700 | C25: -338 | D25: =C25*10^-3 -> -0.338 | E25: =((D25)^2/B25)/D_Calculation_electrode_area!$H$21 -> 0.0067175679 | F25: =E25/D25 -> -0.019874461
A26: S1 | B26: 1000 | C26: -136 | D26: =C26*10^-3 -> -0.136 | E26: =((D26)^2/B26)/D_Calculation_electrode_area!$H$21 -> 0.0051115703 | F26: =E26/D26 -> -0.037585076
A27: S1 | B27: 560 | C27: -85 | D27: =C27*10^-3 -> -0.085 | E27: =((D27)^2/B27)/D_Calculation_electrode_area!$H$21 -> 0.0035655485 | F27: =E27/D27 -> -0.041947629
A28: S1 | B28: 100 | C28: -17.7 | D28: =C28*10^-3 -> -0.0177 | E28: =((D28)^2/B28)/D_Calculation_electrode_area!$H$21 -> 0.00086581092 | F28: =E28/D28 -> -0.048915871
A29: S1 | B29: 10 | C29: -1.8 | D29: =C29*10^-3 -> -0.0018 | E29: =((D29)^2/B29)/D_Calculation_electrode_area!$H$21 -> 8.9540916e-05 | F29: =E29/D29 -> -0.049744953
A30: S2 | B30: 10000 | C30: -287 | D30: =C30*10^-3 -> -0.287 | E30: =((D30)^2/B30)/D_Calculation_electrode_area!$H$21 -> 0.0022763567 | F30: =E30/D30 -> -0.0079315565
A31: S2 | B31: 6800 | C31: -183 | D31: =C31*10^-3 -> -0.183 | E31: =((D31)^2/B31)/D_Calculation_electrode_area!$H$21 -> 0.0013610366 | F31: =E31/D31 -> -0.0074373582
A32: S2 | B32: 4700 | C32: -149 | D32: =C32*10^-3 -> -0.149 | E32: =((D32)^2/B32)/D_Calculation_electrode_area!$H$21 -> 0.0013054228 | F32: =E32/D32 -> -0.008761227
A33: S2 | B33: 1000 | C33: -48 | D33: =C33*10^-3 -> -0.048 | E33: =((D33)^2/B33)/D_Calculation_electrode_area!$H$21 -> 0.0006367354 | F33: =E33/D33 -> -0.013265321
A34: S2 | B34: 560 | C34: -30 | D34: =C34*10^-3 -> -0.03 | E34: =((D34)^2/B34)/D_Calculation_electrode_area!$H$21 -> 0.00044415137 | F34: =E34/D34 -> -0.014805046
... A43: S3 | B43: 10 | C43: -1.2 | D43: =C43*10^-3 -> -0.0012 | E43: =((D43)^2/B43)/D_Calculation_electrode_area!$H$21 -> 3.9795963e-05 | F43: =E43/D43 -> -0.033163302
A44: CC | B44: 10000 | C44: -212.2 | D44: =C44*10^-3 -> -0.2122 | E44: =((D44)^2/B44)/D_Calculation_electrode_area!$H$22 -> 2.5016017e-10 | F44: =E44/D44 -> -1.1788887e-09
A45: CC | B45: 6800 | C45: -175.8 | D45: =C45*10^-3 -> -0.1758 | E45: =((D45)^2/B45)/D_Calculation_electrode_area!$H$22 -> 2.5249701e-10 | F45: =E45/D45 -> -1.4362742e-09
A46: CC | B46: 4700 | C46: -127.3 | D46: =C46*10^-3 -> -0.1273 | E46: =((D46)^2/B46)/D_Calculation_electrode_area!$H$22 -> 1.9155185e-10 | F46: =E46/D46 -> -1.5047278e-09
A47: CC | B47: 1000 | C47: -37.48 | D47: =C47*10^-3 -> -0.03748 | E47: =((D47)^2/B47)/D_Calculation_electrode_area!$H$22 -> 7.8041673e-11 | F47: =E47/D47 -> -2.0822218e-09
A48: CC | B48: 560 | C48: -16.7 | D48: =C48*10^-3 -> -0.0167 | E48: =((D48)^2/B48)/D_Calculation_electrode_area!$H$22 -> 2.7667653e-11 | F48: =E48/D48 -> -1.6567457e-09
A49: CC | B49: 100 | C49: -2.65 | D49: =C49*10^-3 -> -0.00265 | E49: =((D49)^2/B49)/D_Calculation_electrode_area!$H$22 -> 3.9013881e-12 | F49: =E49/D49 -> -1.4722219e-09
A50: CC | B50: 10 | C50: -0.25 | D50: =C50*10^-3 -> -0.00025 | E50: =((D50)^2/B50)/D_Calculation_electrode_area!$H$22 -> 3.4722215e-13 | F50: =E50/D50 -> -1.3888886e-09
A51: SC | B51: 10000 | C51: -203.1 | D51: =C51*10^-3 -> -0.2031 | E51: =((D51)^2/B51)/D_Calculation_electrode_area!$H$21 -> 0.0011399777 | F51: =E51/D51 -> -0.0056128889
A52: SC | B52: 6800 | C52: -169.4 | D52: =C52*10^-3 -> -0.1694 | E52: =((D52)^2/B52)/D_Calculation_electrode_area!$H$21 -> 0.0011662574 | F52: =E52/D52 -> -0.0068846365
A53: SC | B53: 4700 | C53: -116.7 | D53: =C53*10^-3 -> -0.1167 | E53: =((D53)^2/B53)/D_Calculation_electrode_area!$H$21 -> 0.0008007932 | F53: =E53/D53 -> -0.0068619812
A54: SC | B54: 1000 | C54: -25.45 | D54: =C54*10^-3 -> -0.02545 | E54: =((D54)^2/B54)/D_Calculation_electrode_area!$H$21 -> 0.00017899962 | F54: =E54/D54 -> -0.0070333837
A55: SC | B55: 560 | C55: -23.44 | D55: =C55*10^-3 -> -0.02344 | E55: =((D55)^2/B55)/D_Calculation_electrode_area!$H$21 -> 0.00027114632 | F55: =E55/D55 -> -0.011567676
A56: SC | B56: 100 | C56: -5.14 | D56: =C56*10^-3 -> -0.00514 | E56: =((D56)^2/B56)/D_Calculation_electrode_area!$H$21 -> 7.3013432e-05 | F56: =E56/D56 -> -0.014204948
...

Sheet D_Calculation_electrode_area
A4: Big electrode area (BOX) | G4: Small electrode area (Reactor)
A5: Net diameter | B5: 0.5 | C5: mm | G5: Net diameter | H5: 0.5 | I5: mm
A6: Net radius | B6: =B5/2 -> 0.25 | C6: mm | G6: Net radius | H6: =H5/2 -> 0.25 | I6: mm
A7: Electrode width | B7: 150 | C7: mm | G7: Electrode width | H7: 80 | I7: mm
A8: Electrode depth | B8: 150 | C8: mm | G8: Electrode depth | H8: 80 | I8: mm
A9: Treads pr. mm | B9: 0.1 | C9: tread pr. mm | G9: Treads pr. mm | H9: 0.1 | I9: tread pr. mm
A10: Welding | B10: 1 | C10: mm pr. welding | G10: Welding | H10: 1 | I10: mm pr. welding
A11: Amount of weldings | B11: =15*15*2 -> 450 | C11: weldings | G11: Amount of weldings | H11: =8*8*2 -> 128 | I11: weldings
A12: Total length of electrode wire | B12: =B9*B8*B8+B9*B7*B7-B10*B11 -> 4050 | C12: mm | G12: Total length of electrode wire | H12: =H9*H8*H8+H9*H7*H7-H10*H11 -> 1152 | I12: mm
A13: Pi | B13: 3.14 | G13: Pi | H13: 3.14
G15: Coal area | H15: =1200 -> 1200 | I15: m2/g
A16: Projected area | B16: =2*B13*B6*(B6+B12)+1*B13*B6^2 -> 6359.0887 | C16: mm^2 | G16: mass of coal | H16: 15 | I16: g
A17: Projected area | B17: =B16*10^-6 -> 0.0063590887 | C17: m^2 | G17: Total coal surface area | H17: =H15*H16 -> 18000 | I17: m2
A18: Actual area | B18: =B16*2 -> 12718.177 | C18: mm^2
A19: Actual area | B19: =B18*10^-6 -> 0.012718177 | C19: m^2 | G19: Projected area (without coal) | H19: =2*H13*H6*(H6+H12)+1*H13*H6^2 -> 1809.2287 | I19: mm^2
G20: Projected area | H20: =H19*10^-6+H17 -> 18000.002 | I20: m^2
G21: Actual area (without coal) | H21: =H19*2*10^-6 -> 0.0036184575 | I21: m^2
G22: Actual area | H22: =H21+H17 -> 18000.004 | I22: m^2
A23: Calculating the length of steel without coal

Sheet E_Barplots
A1: Reactor | B1: S1 [mol/L] | C1: S2 [mol/L] | D1: Day | F1: Reactor | G1: S1 [mol/L] | H1: S2 [mol/L] | I1: Day
A2: C1 | B2: 0.00649 | C2: 5.1055e-06 | D2: 0 | F2: S1 | G2: 0.00677 | H2: 6.39655e-06 | I2: 0
A3: C2 | B3: 0.00685 | C3: 8.0397e-06 | F3: S2 | G3: 0.00706 | H3: 1.10619e-05
A4: C3 | B4: 0.0057 | C4: 8.33312e-06 | F4: S3 | G4: 0.00639 | H4: 3.43301e-05
A5: CC1 | B5: 0.00655 | C5: 1.00936e-05 | F5: SC1 | G5: 0.00744 | H5: 8.28324e-07
A6: CC2 | B6: 0.00588 | C6: 1.27344e-05 | F6: SC2 | G6: 0.00739 | H6: 3.5894e-06
A7: CC3 | B7: 0.00657 | C7: 9.77087e-06 | F7: SC3 | G7: 0.00739 | H7: 3.89312e-06
A8: RC1 | B8: 0.0059 | C8: 1.40548e-05 | F8: RC1 | G8: 0.0059 | H8: 1.40548e-05
A9: RC2 | B9: 0.00652 | C9: 8.71456e-06 | F9: RC2 | G9: 0.00652 | H9: 8.71456e-06
A10: RC3 | B10: 0.00594 | C10: 8.53851e-06 | F10: RC3 | G10: 0.00594 | H10: 8.53851e-06
A11: C1 | B11: 0.00494 | C11: 5.80971e-05 | D11: 9 | F11: S1 | G11: 0.00588 | H11: 0.00022564 | I11: 9
A12: C2 | B12: 0.00499 | C12: 9.68285e-05 | F12: S2 | G12: 0.00599 | H12: 0.000334498
A13: C3 | B13: 0.00359 | C13: 0.000110326 | F13: S3 | G13: 0.0052 | H13: 0.000360906
A14: CC1 | B14: 0.00451 | C14: 9.91758e-05 | F14: SC1 | G14: 0.00378 | H14: 0.000139987
A15: CC2 | B15: 0.00403 | C15: 0.000152578 | F15: SC2 | G15: 0.0064 | H15: 6.68181e-05
A16: CC3 | B16: 0.00538 | C16: 0.000107392 | F16: SC3 | G16: 0.00645 | H16: 5.41171e-05
A17: RC1 | B17: 0.00511 | C17: 0.000466537 | F17: RC1 | G17: 0.00511 | H17: 0.000466537
A18: RC2 | B18: 0.00547 | C18: 0.000369709 | F18: RC2 | G18: 0.00547 | H18: 0.000369709
A19: RC3 | B19: 0.00547 | C19: 0.00019395 | F19: RC3 | G19: 0.00547 | H19: 0.00019395
A20: C1 | B20: 0.00496 | C20: 3.46235e-05 | D20: 16 | F20: S1 | G20: 0.00599 | H20: 9.36009e-05 | I20: 16
A21: C2 | B21: 0.00519 | C21: 0.000115314 | F21: S2 | G21: 0.00609 | H21: 0.000346235
A22: C3 | B22: 0.00494 | C22: 3.37433e-05 | F22: S3 | G22: 0.00493 | H22: 0.000809838
A23: CC1 | B23: 0.00506 | C23: 0.000115901 | F23: SC1 | G23: 0.00573 | H23: 0.000225304
A24: CC2 | B24: 0.00433 | C24: 0.000195711 | F24: SC2 | G24: 0.00583 | H24: 0.000339613
A25: CC3 | B25: 0.00511 | C25: 0.000107978 | F25: SC3 | G25: 0.00583 | H25: 0.000226547
A26: RC1 | B26: 0.00505 | C26: 0.001166343 | F26: RC1 | G26: 0.00505 | H26: 0.001166343
A27: RC2 | B27: 0.00536 | C27: 0.000668997 | F27: RC2 | G27: 0.00536 | H27: 0.000668997
A28: RC3 | B28: 0.0052 | C28: 0.000498813 | F28: RC3 | G28: 0.0052 | H28: 0.000498813
A29: C1 | B29: 0.00438 | C29: 2.86378e-05 | D29: 23 | F29: S1 | G29: 0.00562 | H29: 0.000166662 | I29: 23
A30: C2 | B30: 0.00431 | C30: 7.57023e-05 | F30: S2 | G30: 0.00541 | H30: 0.000513484
A31: C3 | B31: 0.00418 | C31: 3.94356e-05 | F31: S3 | G31: 0.00412 | H31: 0.000915469
A32: CC1 | B32: 0.00355 | C32: 0.000169597 | F32: SC1 | G32: 0.00242 | H32: 0.000445086
A33: CC2 | B33: 0.00321 | C33: 0.000316893 | F33: SC2 | G33: 0.00464 | H33: 0.000187201
A34: CC3 | B34: 0.00396 | C34: 0.000121769 | F34: SC3 | G34: 0.00488 | H34: 0.00027666
A35: RC1 | B35: 0.00463 | C35: 0.000514951 | F35: RC1 | G35: 0.00463 | H35: 0.000514951
A36: RC2 | B36: 0.00428 | C36: 0.00098589 | F36: RC2 | G36: 0.00428 | H36: 0.00098589
A37: RC3 | B37: 0.00472 | C37: 0.000651392 | F37: RC3 | G37: 0.00472 | H37: 0.000651392
A38: C1 | B38: 0.00396 | C38: 2.37083e-05 | D38: 30 | F38: S1 | G38: 0.00593 | H38: 0.000253515 | I38: 30
A39: C2 | B39: 0.00399 | C39: 0.000135912 | F39: S2 | G39: 0.00578 | H39: 0.000450693
A40: C3 | B40: 0.00387 | C40: 3.56798e-05 | F40: S3 | G40: 0.00403 | H40: 0.00089493
...

Sheet F_IPC_MS
A1: ICP-MS analysis
A3: 2022-05-10/11/12/18
A4: Isabella Joensen
A8: Conc. RSD = The same injection analysed 3 times.
A9: Method detection limit is calculated from the calibration curve.
A10: Samples are diluted 10 fold - result is back calculated
H13: Fe 56 [ He ] | K13: Ni 60 [ He ] | M13: Cu 63 [ He ] | O13: Cr 52 [ He ] | Q13: Al 27 [ He ] | T13: P 31 [ He ]
A14: Controls (n=4) | G14: Ref. value (ug/l) | H14: 25.2 | K14: 12.4 | M14: 24.4 | O14: 12.5 | Q14: 15.0 | T14: 10.7
A15: EnvMAT driking water, Cert Ref Standard (%RSD) 100 & 2000 fold | H15: 1.2 | K15: 2.5 | M15: 2.3 | O15: 1.6 | Q15: 6.5 | T15: 29.6
A16: EnvMAT driking water, Cert Ref Standard (%Recovery) | H16: 97.9 | K16: 95.0 | M16: 94.8 | O16: 94.7 | Q16: 97.8 | T16: 97.8
D19: S 181,975 | H19: Fe 56 [ He ] | K19: Ni 60 [ He ] | M19: Cu 63 [ He ] | O19: Cr 52 [ He ] | Q19: Al 27 [ He ] | T19: P 31 [ He ]
A20: MDL (ug/l) | C20: MDL (mg/l) | D20: 5.00 | G20: MDL (ug/l) | H20: 2.00 | K20: 0.50 | M20: 0.50 | O20: 0.50 | Q20: 5.00 | S20: MDL (mg/l) | T20: 1.00
A22: Sample name | B22: Date | C22: Reactor | D22: Conc. [ mg/l ] | E22: Conc [mol/L] | F22: Conc. RSD | H22: Conc. [ ug/l ] | I22: Conc. [mol/L] | J22: Conc. RSD | K22: Conc. [ ug/l ] | L22: Conc. RSD | M22: Conc. [ ug/l ] | N22: Conc. RSD | O22: Conc. [ ug/l ] | P22: Conc. RSD | Q22: Conc. [ ug/l ] | R22: Conc. RSD | T22: Conc. [ ug/l ] | U22: Conc. RSD
A23: 1 | B23: 44643 | C23: C1 | D23: 206.26 | E23: 6.43E-03 | F23: 2.53% | H23: 72.17 | I23: 1.29E-06 | J23: 2.10% | K23: 1.66 | L23: 6.42% | M23: < 0,5 | N23: - | O23: 1.89 | P23: 12.21% | Q23: < 5 | R23: - | T23: 9.46 | U23: 2.97%
A24: 2 | B24: 44643 | C24: C2 | D24: 207.98 | E24: 6.49E-03 | F24: 0.74% | H24: 36.12 | I24: 6.47E-07 | J24: 2.51% | K24: 1.68 | L24: 10.13% | M24: < 0,5 | N24: - | O24: 2.01 | P24: 6.61% | Q24: < 5 | R24: - | T24: 10.13 | U24: 0.81%
A25: 3 | B25: 44643 | C25: C3 | D25: 192.73 | E25: 6.01E-03 | F25: 1.75% | H25: 88.49 | I25: 1.58E-06 | J25: 2.46% | K25: 1.71 | L25: 23.12% | M25: < 0,5 | N25: - | O25: 1.82 | P25: 13.45% | Q25: < 5 | R25: - | T25: 10.49 | U25: 0.90%
A26: 4 | B26: 44643 | C26: CC1 | D26: 185.26 | E26: 5.78E-03 | F26: 3.17% | H26: 48.97 | I26: 8.77E-07 | J26: 4.04% | K26: 1.58 | L26: 14.06% | M26: < 0,5 | N26: - | O26: 2.14 | P26: 6.43% | Q26: < 5 | R26: - | T26: 10.08 | U26: 3.47%
A27: 5 | B27: 44643 | C27: CC2 | D27: 168.80 | E27: 5.26E-03 | F27: 1.05% | H27: 28.10 | I27: 5.03E-07 | J27: 4.53% | K27: 1.72 | L27: 12.05% | M27: < 0,5 | N27: - | O27: 2.25 | P27: 11.76% | Q27: < 5 | R27: - | T27: 10.71 | U27: 1.88%
A28: 6 | B28: 44643 | C28: CC3 | D28: 194.28 | E28: 6.06E-03 | F28: 0.27% | H28: 52.07 | I28: 9.32E-07 | J28: 2.52% | K28: 1.39 | L28: 26.85% | M28: < 0,5 | N28: - | O28: 1.65 | P28: 20.18% | Q28: < 5 | R28: - | T28: 10.15 | U28: 0.92%
A29: 7 | B29: 44643 | C29: S1 | D29: 223.24 | E29: 6.96E-03 | F29: 1.08% | H29: 60.02 | I29: 1.07E-06 | J29: 1.19% | K29: 1.17 | L29: 12.09% | M29: < 0,5 | N29: - | O29: 1.65 | P29: 11.90% | Q29: < 5 | R29: - | T29: 7.93 | U29: 1.91%
A30: 8 | B30: 44643 | C30: S2 | D30: 228.33 | E30: 7.12E-03 | F30: 0.59% | H30: 20.90 | I30: 3.74E-07 | J30: 9.77% | K30: 1.08 | L30: 15.75% | M30: < 0,5 | N30: - | O30: 1.58 | P30: 9.29% | Q30: < 5 | R30: - | T30: 7.80 | U30: 1.44%
A31: 9 | B31: 44643 | C31: S3 | D31: 191.11 | E31: 5.96E-03 | F31: 0.57% | H31: 26.87 | I31: 4.81E-07 | J31: 2.12% | K31: 1.44 | L31: 6.56% | M31: < 0,5 | N31: - | O31: 2.00 | P31: 9.32% | Q31: < 5 | R31: - | T31: 9.58 | U31: 0.35%
A32: 10 | B32: 44643 | C32: RC1 | D32: 187.53 | E32: 5.85E-03 | F32: 0.98% | H32: 12.65 | I32: 2.26E-07 | J32: 6.68% | K32: 1.12 | L32: 6.41% | M32: 0.55 | N32: 23.16% | O32: 1.55 | P32: 3.27% | Q32: < 5 | R32: - | T32: 8.95 | U32: 1.27%
A33: 11 | B33: 44643 | C33: RC2 | D33: 197.28 | E33: 6.15E-03 | F33: 2.18% | H33: 17.44 | I33: 3.12E-07 | J33: 3.10% | K33: 1.18 | L33: 1.10% | M33: < 0,5 | N33: - | O33: 1.95 | P33: 16.24% | Q33: < 5 | R33: - | T33: 7.89 | U33: 2.87%
A34: 12 | B34: 44643 | C34: RC3 | D34: 195.61 | E34: 6.10E-03 | F34: 2.40% | H34: 16.52 | I34: 2.96E-07 | J34: 7.18% | K34: 0.99 | L34: 3.59% | M34: < 0,5 | N34: - | O34: 0.75 | P34: 12.33% | Q34: < 5 | R34: - | T34: 8.15 | U34: 1.44%
... A157: 135 | B157: 44678 | C157: CB3 | D157: 292.29 | E157: 9.12E-03 | F157: 1.87% | H157: 4.07 | I157: 7.30E-08 | J157: 12.27% | K157: 0.96 | L157: 5.67% | M157: 3.59 | N157: 1.63% | O157: < 0,5 | P157: - | Q157: < 5 | R157: - | T157: 1.15 | U157: 1.68%
A159: M_S | B159: 32065 | C159: g/mol
A160: M_Fe | B160: 55845 | C160: g/mol
A162: Difference between 1. and 5 measurement | B162: S | C162: Fe
A163: R1 | B163: 1148234966 | C163: -1.97E-03
A164: R2 | B164: 1353610402 | C164: -1.73E-03
A165: R3 | B165: 0.119905885 | C165: -6.42E-03
A166: R4 | B166: 2434437233 | C166: 6.80E-04
A167: R5 | B167: 2452716292 | C167: 3.52E-04
A168: R6 | B168: 2385588687 | C168: 6.91E-04
A169: R7 | B169: 0.109452108 | C169: 1.88E-04
A170: R8 | B170: 0.369360047 | C170: -6.49E-04
A171: R9 | B171: 1141223865 | C171: -1.00E-04
A172: R10 | B172: 1008802352 | C172: -9.14E-04
A173: R11 | B173: 1849873662 | C173: 3.26E-05
...
